<?xml version='1.0'?>

<robot name="jetbot" xmlns:xacro="http://www.ros.org/wiki/xacro">

  
    <link name="base_footprint"/>

    
    <joint name="base_footprint_joint" type="fixed">
        <origin xyz="0 0 0.0" rpy="0 0 0" />
        <parent link="base_footprint"/>
        <child link="base_link"/>
    </joint>

    <link name="base_link">
        <inertial>
            <origin xyz="0.0 0.0 0.0" rpy="0.0 0.0 0.0"/>
            <mass value="5.0"/>
            <inertia ixx="0.0" ixy="0.0" ixz="0.0" iyy="0.0" iyz="0.0" izz="0.0"/>
        </inertial>
        <visual name="base_link_visual">
            <origin xyz="0.0 0.0 0.0" rpy="0.0 0.0 0.0"/>
            <geometry>
                <box size="0.65 0.6 0.1"/>
            </geometry>
            <material name="">
                <color rgba="0.0 0.0 1.0 1.0"/>
                <texture filename=""/>
            </material>
        </visual>
        <collision>
            <origin xyz="0.0 0.0 0.0" rpy="0.0 0.0 0.0"/>
            <geometry>
                <box size="0.4 0.2 0.1"/>
            </geometry>
        </collision>
    </link>

    <link name="front_left_wheel">
        <inertial>
            <origin xyz="0.0 0.0 0.0" rpy="0.0 1.5707 1.5707"/>
            <mass value="5.0"/>
            <inertia ixx="0.1" ixy="0.0" ixz="0.0" iyy="0.1" iyz="0.0" izz="0.1"/>
        </inertial>
        <visual name="left_wheel_visual">
            <origin xyz="0.0 0.0 0.0" rpy="0.0 0.0 0.0"/>
            <geometry>
                <cylinder radius="0.1" length="0.02"/>
            </geometry>
        </visual>
        <collision name='left_wheel_collision'>
            <origin xyz="0.0 0.0 0.0" rpy="0.0 0.0 0.0"/>
            <geometry>
                <cylinder radius="0.1" length="0.02"/>
            </geometry>
        </collision>
    </link>


    <joint name="front_left_wheel_joint" type="continuous">
        <origin xyz="0.2 0.35 -0.035" rpy="0.0 1.5705 1.5705"/>
        <parent link="base_link"/>
        <child link="front_left_wheel"/>
        <axis xyz="0.0 0.0 1.0"/>

    </joint>



    <link name="front_right_wheel">
        <inertial>
            <origin xyz="0.0 0.0 0.0" rpy="0.0 0.0 0.0"/>
            <mass value="5.0"/>
            <inertia ixx="0.1" ixy="0.0" ixz="0.0" iyy="0.1" iyz="0.0" izz="0.1"/>
        </inertial>
        <visual name="right_wheel_visual">
            <origin xyz="0.0 0.0 0.0" rpy="0.0 0.0 0.0"/>
            <geometry>
                <cylinder radius="0.1" length="0.02"/>
            </geometry>
        </visual>
        <collision name='right_wheel_collision'>
            <origin xyz="0.0 0.0 0.0" rpy="0.0 0.0 0.0"/>
            <geometry>
                <cylinder radius="0.1" length="0.02"/>
            </geometry>
        </collision>
    </link>


    <joint name="front_right_wheel_joint" type="continuous">
        <origin xyz="0.2 -0.35 -0.035" rpy="0.0 1.5705 1.5705"/>
        <parent link="base_link"/>
        <child link="front_right_wheel"/>
        <axis xyz="0.0 0.0 1.0"/>

    </joint>

    <link name="back_left_wheel">
        <inertial>
            <origin xyz="0.0 0.0 0.0" rpy="0.0 1.5707 1.5707"/>
            <mass value="5.0"/>
            <inertia ixx="0.1" ixy="0.0" ixz="0.0" iyy="0.1" iyz="0.0" izz="0.1"/>
        </inertial>
        <visual name="left_wheel_visual">
            <origin xyz="0.0 0.0 0.0" rpy="0.0 0.0 0.0"/>
            <geometry>
                <cylinder radius="0.1" length="0.02"/>
            </geometry>
        </visual>
        <collision name='left_wheel_collision'>
            <origin xyz="0.0 0.0 0.0" rpy="0.0 0.0 0.0"/>
            <geometry>
                <cylinder radius="0.1" length="0.02"/>
            </geometry>
        </collision>
    </link>


    <joint name="back_left_wheel_joint" type="continuous">
       <origin xyz="-0.2 0.35 -0.035" rpy="0.0 1.5705 1.5705"/>
        <parent link="base_link"/>
        <child link="back_left_wheel"/>
        <axis xyz="0.0 0.0 1.0"/>

    </joint>



    <link name="back_right_wheel">
        <inertial>
            <origin xyz="0.0 0.0 0.0" rpy="0.0 0.0 0.0"/>
            <mass value="5.0"/>
            <inertia ixx="0.1" ixy="0.0" ixz="0.0" iyy="0.1" iyz="0.0" izz="0.1"/>
        </inertial>
        <visual name="right_wheel_visual">
            <origin xyz="0.0 0.0 0.0" rpy="0.0 0.0 0.0"/>
            <geometry>
                <cylinder radius="0.1" length="0.02"/>
            </geometry>
        </visual>
        <collision name='right_wheel_collision'>
            <origin xyz="0.0 0.0 0.0" rpy="0.0 0.0 0.0"/>
            <geometry>
                <cylinder radius="0.1" length="0.02"/>
            </geometry>
        </collision>
    </link>


    <joint name="back_right_wheel_joint" type="continuous">
        <origin xyz="-0.2 -0.35 -0.035" rpy="0.0 1.5705 1.5705"/>
        <parent link="base_link"/>
        <child link="back_right_wheel"/>
        <axis xyz="0.0 0.0 1.0"/>

    </joint>



    <link name="laser">
        <inertial>
            <origin xyz="0.0 0.0 0.0" rpy="0.0 0.0 0.0"/>
            <mass value="0.1"/>
            <inertia ixx="0.0" ixy="0.0" ixz="0.0" iyy="0.0" iyz="0.0" izz="0.0"/>
        </inertial>
        <visual name="lidar_link_visual">
            <origin xyz="0.0 0.0 0.0" rpy="0.0 0.0 0.0"/>
            <geometry>
                <cylinder radius="0.035" length="0.06"/>
            </geometry>
            <material name="">
                <color rgba="1.0 0.0 0.0 1.0"/>
                <texture filename=""/>
            </material>
        </visual>
        <collision>
            <origin xyz="0.0 0.0 0.0" rpy="0.0 0.0 0.0"/>
            <geometry>
                <cylinder radius="0.035" length="0.02"/>
            </geometry>
        </collision>
    </link>

    <joint name="lidar_joint" type="fixed">
        <origin xyz="0.33 0.0 0.38" rpy="0 0.0 0"/>
        <parent link="base_link"/>
        <child link="laser"/>
    </joint>


    <link name="imu_link">
        <collision>
        <origin xyz="0 0 0.0" rpy="0 0 0"/>
        <geometry>
            <box size="0.02 0.02 0.02"/>
        </geometry>
        </collision>

        <visual>
        <origin xyz="0 0 0.0" rpy="0 0 0"/>
        <geometry>
            <box size="0.02 0.02 0.02"/>
        </geometry>
        </visual>

        <inertial>
        <origin xyz="0 0 1" rpy="0 0 0"/>
        <mass value="1"/>
        <inertia
            ixx="1.0" ixy="0.0" ixz="0.0"
            iyy="1.0" iyz="0.0"
            izz="1.0"/>
        </inertial>
    </link>
    <joint name="imu_joint" type="fixed">
        <origin xyz="-0.1 0.0 0.05" rpy="0.0 0.0 0.0"/>
        <parent link="base_link"/>
        <child link="imu_link"/>
    </joint>

</robot>